Workbook

Sheet Raw_Posts
A1: Post ID | B1: Platform | C1: Date | D1: Content Type | E1: Post Text | F1: Likes | G1: Shares | H1: Comments | I1: Impressions | J1: Reach | K1: Clicks | L1: Hashtags Used | M1: Campaign_Name
A2: P001 | B2: Twitter | C2: 45649 | D2: Reel | E2: Check out our latest reel on twitter! | F2: 1461 | G2: 184 | H2: 344 | I2: 21915 | J2: 21675 | K2: 15 | L2: #LiveForNow,#AnytimeIsPepsiTime | M2: SummerSplash
A3: P002 | B3: Twitter | C3: 45750 | D3: Text | E3: Check out our latest text on twitter! | F3: 4054 | G3: 389 | H3: 493 | I3: 64864 | J3: 64383 | K3: 117 | L3: #PepsiCoRefresh,#BetterWithPepsi | M3: FestiveRadiance
A4: P003 | B4: YouTube | C4: 45789 | D4: Reel | E4: Check out our latest reel on youtube! | F4: 2795 | G4: 105 | H4: 49 | I4: 53105 | J4: 52307 | K4: 204 | L4: #PepsiCoRefresh | M4: NewYearRefresh
A5: P004 | B5: Instagram | C5: 45516 | D5: Story | E5: Check out our latest story on instagram! | F5: 2404 | G5: 363 | H5: 138 | I5: 19232 | J5: 18636 | K5: 128 | L5: #ThirstyForMore | M5: DailyWellness
A6: P005 | B6: YouTube | C6: 45469 | D6: Reel | E6: Check out our latest reel on youtube! | F6: 3557 | G6: 687 | H6: 424 | I6: 71140 | J6: 70701 | K6: 224 | L6: #ThirstyForMore,#PepsiCoRefresh | M6: SummerSplash
A7: P006 | B7: Facebook | C7: 45596 | D7: Carousel | E7: Check out our latest carousel on facebook! | F7: 2945 | G7: 930 | H7: 355 | I7: 23560 | J7: 23275 | K7: 256 | L7: #PepsiCoRefresh | M7: FestiveRadiance
A8: P007 | B8: Twitter | C8: 45467 | D8: Carousel | E8: Check out our latest carousel on twitter! | F8: 3860 | G8: 201 | H8: 279 | I8: 61760 | J8: 61660 | K8: 235 | L8: #PepsiCoRefresh | M8: FestiveRadiance
A9: P008 | B9: YouTube | C9: 45486 | D9: Image | E9: Check out our latest image on youtube! | F9: 3929 | G9: 262 | H9: 278 | I9: 43219 | J9: 42841 | K9: 39 | L9: #ThirstyForMore | M9: DailyWellness
A10: P009 | B10: Facebook | C10: 45534 | D10: Text | E10: Check out our latest text on facebook! | F10: 3784 | G10: 808 | H10: 404 | I10: 56760 | J10: 56343 | K10: 131 | L10: #PepsiCoRefresh | M10: FestiveRadiance
A11: P010 | B11: Facebook | C11: 45727 | D11: Image | E11: Check out our latest image on facebook! | F11: 4241 | G11: 902 | H11: 47 | I11: 72097 | J11: 71598 | K11: 167 | L11: #PepsiCoRefresh | M11: FestiveRadiance
A12: P011 | B12: Instagram | C12: 45690 | D12: Story | E12: Check out our latest story on instagram! | F12: 1792 | G12: 614 | H12: 497 | I12: 25088 | J12: 24675 | K12: 65 | L12: #LiveForNow | M12: DailyWellness
A13: P012 | B13: Facebook | C13: 45494 | D13: Reel | E13: Check out our latest reel on facebook! | F13: 1946 | G13: 686 | H13: 377 | I13: 23352 | J13: 22982 | K13: 213 | L13: #LiveForNow | M13: NewYearRefresh
A14: P013 | B14: YouTube | C14: 45614 | D14: Carousel | E14: Check out our latest carousel on youtube! | F14: 1171 | G14: 286 | H14: 231 | I14: 22249 | J14: 21282 | K14: 114 | L14: #ThirstyForMore | M14: SummerSplash
A15: P014 | B15: Facebook | C15: 45704 | D15: Story | E15: Check out our latest story on facebook! | F15: 4242 | G15: 555 | H15: 131 | I15: 33936 | J15: 33802 | K15: 265 | L15: #LiveForNow
A16: P015 | B16: Facebook | C16: 45589 | D16: Video | E16: Check out our latest video on facebook! | F16: 3888 | G16: 604 | H16: 128 | I16: 77760 | J16: 77167 | K16: 20 | L16: #LiveForNow | M16: SummerSplash
A17: P016 | B17: Facebook | C17: 45530 | D17: Text | E17: Check out our latest text on facebook! | F17: 3452 | G17: 377 | H17: 360 | I17: 55232 | J17: 55075 | K17: 87 | L17: #LiveForNow | M17: NewYearRefresh
A18: P017 | B18: Facebook | C18: 45782 | D18: Text | E18: Check out our latest text on facebook! | F18: 4441 | G18: 511 | H18: 70 | I18: 53292 | J18: 53082 | K18: 159 | L18: #ThirstyForMore | M18: DailyWellness
A19: P018 | B19: Instagram | C19: 45523 | D19: Reel | E19: Check out our latest reel on instagram! | F19: 3000 | G19: 382 | H19: 325 | I19: 36000 | J19: 35819 | K19: 19 | L19: #LiveForNow | M19: SummerSplash
A20: P019 | B20: Instagram | C20: 45466 | D20: Video | E20: Check out our latest video on instagram! | F20: 1071 | G20: 519 | H20: 22 | I20: 16065 | J20: 15865 | K20: 103 | L20: #PepsiCoRefresh | M20: DailyWellness
A21: P020 | B21: Instagram | C21: 45544 | D21: Carousel | E21: Check out our latest carousel on instagram! | F21: 4054 | G21: 488 | H21: 373 | I21: 77026 | J21: 76881 | K21: 25 | L21: #PepsiCoRefresh | M21: SummerSplash
A22: P021 | B22: Instagram | C22: 45661 | D22: Reel | E22: Check out our latest reel on instagram! | F22: 4838 | G22: 640 | H22: 128 | I22: 72570 | J22: 72396 | K22: 83 | L22: #LiveForNow | M22: DailyWellness
A23: P022 | B23: Facebook | C23: 45715 | D23: Text | E23: Check out our latest text on facebook! | F23: 1570 | G23: 187 | H23: 260 | I23: 25120 | J23: 24613 | K23: 133 | L23: #PepsiCoRefresh | M23: DailyWellness
A24: P023 | B24: Facebook | C24: 45602 | D24: Video | E24: Check out our latest video on facebook! | F24: 1606 | G24: 547 | H24: 316 | I24: 32120 | J24: 31736 | K24: 225 | L24: #PepsiCoRefresh,#AnytimeIsPepsiTime | M24: FestiveRadiance
A25: P024 | B25: Facebook | C25: 45680 | D25: Video | E25: Check out our latest video on facebook! | F25: 3961 | G25: 761 | H25: 131 | I25: 67337 | J25: 66615 | K25: 161 | L25: #LiveForNow | M25: NewYearRefresh
A26: P025 | B26: Twitter | C26: 45757 | D26: Carousel | E26: Check out our latest carousel on twitter! | F26: 3128 | G26: 211 | H26: 197 | I26: 59432 | J26: 59182 | K26: 238 | L26: #ThirstyForMore
A27: P026 | B27: YouTube | C27: 45752 | D27: Reel | E27: Check out our latest reel on youtube! | F27: 3009 | G27: 413 | H27: 358 | I27: 42126 | J27: 41309 | K27: 211 | L27: #LiveForNow | M27: FestiveRadiance
A28: P027 | B28: YouTube | C28: 45552 | D28: Text | E28: Check out our latest text on youtube! | F28: 2076 | G28: 195 | H28: 104 | I28: 33216 | J28: 32244 | K28: 51 | L28: #LiveForNow | M28: DailyWellness
A29: P028 | B29: Instagram | C29: 45720 | D29: Video | E29: Check out our latest video on instagram! | F29: 432 | G29: 624 | H29: 123 | I29: 6912 | J29: 6259 | K29: 79 | L29: #LiveForNow | M29: DailyWellness
A30: P029 | B30: Instagram | C30: 45688 | D30: Carousel | E30: Check out our latest carousel on instagram! | F30: 2566 | G30: 118 | H30: 37 | I30: 12830 | J30: 12264 | K30: 221 | L30: #LiveForNow | M30: NewYearRefresh
A31: P030 | B31: Instagram | C31: 45713 | D31: Video | E31: Check out our latest video on instagram! | F31: 3095 | G31: 39 | H31: 78 | I31: 55710 | J31: 54808 | K31: 93 | L31: #ThirstyForMore
A32: P031 | B32: Instagram | C32: 45642 | D32: Text | E32: Check out our latest text on instagram! | F32: 438 | G32: 153 | H32: 275 | I32: 3066 | J32: 2701 | K32: 282 | L32: #PepsiCoRefresh | M32: FestiveRadiance
A33: P032 | B33: Twitter | C33: 45504 | D33: Carousel | E33: Check out our latest carousel on twitter! | F33: 2278 | G33: 10 | H33: 321 | I33: 13668 | J33: 12676 | K33: 275 | L33: #ThirstyForMore | M33: SummerSplash
A34: P033 | B34: Facebook | C34: 45525 | D34: Image | E34: Check out our latest image on facebook! | F34: 1407 | G34: 400 | H34: 351 | I34: 16884 | J34: 15954 | K34: 113 | L34: #PepsiCoRefresh | M34: SummerSplash
A35: P034 | B35: Facebook | C35: 45742 | D35: Text | E35: Check out our latest text on facebook! | F35: 1652 | G35: 89 | H35: 357 | I35: 29736 | J35: 28771 | K35: 215 | L35: #PepsiCoRefresh | M35: NewYearRefresh
A36: P035 | B36: Instagram | C36: 45626 | D36: Video | E36: Check out our latest video on instagram! | F36: 3775 | G36: 16 | H36: 239 | I36: 33975 | J36: 33310 | K36: 271 | L36: #LiveForNow | M36: FestiveRadiance
A37: P036 | B37: Instagram | C37: 45766 | D37: Story | E37: Check out our latest story on instagram! | F37: 4518 | G37: 285 | H37: 383 | I37: 67770 | J37: 67621 | K37: 31 | L37: #ThirstyForMore | M37: FestiveRadiance
A38: P037 | B38: Facebook | C38: 45663 | D38: Carousel | E38: Check out our latest carousel on facebook! | F38: 3024 | G38: 925 | H38: 350 | I38: 24192 | J38: 23518 | K38: 36 | L38: #ThirstyForMore | M38: FestiveRadiance
A39: P038 | B39: YouTube | C39: 45705 | D39: Reel | E39: Check out our latest reel on youtube! | F39: 3138 | G39: 123 | H39: 291 | I39: 28242 | J39: 27550 | K39: 87 | L39: #PepsiCoRefresh | M39: DailyWellness
A40: P039 | B40: Facebook | C40: 45621 | D40: Image | E40: Check out our latest image on facebook! | F40: 3564 | G40: 629 | H40: 177 | I40: 60588 | J40: 59627 | K40: 92 | L40: #PepsiCoRefresh
...

Sheet Cleaned_Posts 
A1: Post ID | B1: Platform | C1: Date | D1: Content Type | E1: Post Text | F1: Likes | G1: Shares | H1: Comments | I1: Impressions | J1: Reach | K1: Clicks | L1: Hashtags Used | M1: Campaign_Name | N1: Campaign_Phase
A2: P001 | B2: Twitter | C2: 45649 | D2: Reel | E2: Check out our latest reel on twitter! | F2: 1461 | G2: 184 | H2: 344 | I2: 21915 | J2: 21675 | K2: 15 | L2: #LiveForNow,#AnytimeIsPepsiTime | M2: SummerSplash | N2: =IF(M2="","No Campaign", IF(AND(C2>=VLOOKUP(M2,Cleaned_Campaign_Data!B:D,2,FALSE), C2<=VLOOKUP(M2,Cleaned_Campaign_Data!B:D,3,FALSE)), "During","Before")) -> Before
A3: P002 | B3: Twitter | C3: 45750 | D3: Text | E3: Check out our latest text on twitter! | F3: 4054 | G3: 389 | H3: 493 | I3: 64864 | J3: 64383 | K3: 117 | L3: #PepsiCoRefresh,#BetterWithPepsi | M3: FestiveRadiance | N3: =IF(M3="","No Campaign", IF(AND(C3>=VLOOKUP(M3,Cleaned_Campaign_Data!B:D,2,FALSE), C3<=VLOOKUP(M3,Cleaned_Campaign_Data!B:D,3,FALSE)), "During","Before")) -> Before
A4: P003 | B4: YouTube | C4: 45789 | D4: Reel | E4: Check out our latest reel on youtube! | F4: 2795 | G4: 105 | H4: 49 | I4: 53105 | J4: 52307 | K4: 204 | L4: #PepsiCoRefresh | M4: NewYearRefresh | N4: =IF(M4="","No Campaign", IF(AND(C4>=VLOOKUP(M4,Cleaned_Campaign_Data!B:D,2,FALSE), C4<=VLOOKUP(M4,Cleaned_Campaign_Data!B:D,3,FALSE)), "During","Before")) -> Before
A5: P004 | B5: Instagram | C5: 45516 | D5: Story | E5: Check out our latest story on instagram! | F5: 2404 | G5: 363 | H5: 138 | I5: 19232 | J5: 18636 | K5: 128 | L5: #ThirstyForMore | M5: DailyWellness | N5: =IF(M5="","No Campaign", IF(AND(C5>=VLOOKUP(M5,Cleaned_Campaign_Data!B:D,2,FALSE), C5<=VLOOKUP(M5,Cleaned_Campaign_Data!B:D,3,FALSE)), "During","Before")) -> Before
A6: P005 | B6: YouTube | C6: 45469 | D6: Reel | E6: Check out our latest reel on youtube! | F6: 3557 | G6: 687 | H6: 424 | I6: 71140 | J6: 70701 | K6: 224 | L6: #ThirstyForMore,#PepsiCoRefresh | M6: SummerSplash | N6: =IF(M6="","No Campaign", IF(AND(C6>=VLOOKUP(M6,Cleaned_Campaign_Data!B:D,2,FALSE), C6<=VLOOKUP(M6,Cleaned_Campaign_Data!B:D,3,FALSE)), "During","Before")) -> During
A7: P006 | B7: Facebook | C7: 45596 | D7: Carousel | E7: Check out our latest carousel on facebook! | F7: 2945 | G7: 930 | H7: 355 | I7: 23560 | J7: 23275 | K7: 256 | L7: #PepsiCoRefresh | M7: FestiveRadiance | N7: =IF(M7="","No Campaign", IF(AND(C7>=VLOOKUP(M7,Cleaned_Campaign_Data!B:D,2,FALSE), C7<=VLOOKUP(M7,Cleaned_Campaign_Data!B:D,3,FALSE)), "During","Before")) -> During
A8: P007 | B8: Twitter | C8: 45467 | D8: Carousel | E8: Check out our latest carousel on twitter! | F8: 3860 | G8: 201 | H8: 279 | I8: 61760 | J8: 61660 | K8: 235 | L8: #PepsiCoRefresh | M8: FestiveRadiance | N8: =IF(M8="","No Campaign", IF(AND(C8>=VLOOKUP(M8,Cleaned_Campaign_Data!B:D,2,FALSE), C8<=VLOOKUP(M8,Cleaned_Campaign_Data!B:D,3,FALSE)), "During","Before")) -> Before
A9: P008 | B9: YouTube | C9: 45486 | D9: Image | E9: Check out our latest image on youtube! | F9: 3929 | G9: 262 | H9: 278 | I9: 43219 | J9: 42841 | K9: 39 | L9: #ThirstyForMore | M9: DailyWellness | N9: =IF(M9="","No Campaign", IF(AND(C9>=VLOOKUP(M9,Cleaned_Campaign_Data!B:D,2,FALSE), C9<=VLOOKUP(M9,Cleaned_Campaign_Data!B:D,3,FALSE)), "During","Before")) -> Before
A10: P009 | B10: Facebook | C10: 45534 | D10: Text | E10: Check out our latest text on facebook! | F10: 3784 | G10: 808 | H10: 404 | I10: 56760 | J10: 56343 | K10: 131 | L10: #PepsiCoRefresh | M10: FestiveRadiance | N10: =IF(M10="","No Campaign", IF(AND(C10>=VLOOKUP(M10,Cleaned_Campaign_Data!B:D,2,FALSE), C10<=VLOOKUP(M10,Cleaned_Campaign_Data!B:D,3,FALSE)), "During","Before")) -> Before
A11: P010 | B11: Facebook | C11: 45727 | D11: Image | E11: Check out our latest image on facebook! | F11: 4241 | G11: 902 | H11: 47 | I11: 72097 | J11: 71598 | K11: 167 | L11: #PepsiCoRefresh | M11: FestiveRadiance | N11: =IF(M11="","No Campaign", IF(AND(C11>=VLOOKUP(M11,Cleaned_Campaign_Data!B:D,2,FALSE), C11<=VLOOKUP(M11,Cleaned_Campaign_Data!B:D,3,FALSE)), "During","Before")) -> Before
A12: P011 | B12: Instagram | C12: 45690 | D12: Story | E12: Check out our latest story on instagram! | F12: 1792 | G12: 614 | H12: 497 | I12: 25088 | J12: 24675 | K12: 65 | L12: #LiveForNow | M12: DailyWellness | N12: =IF(M12="","No Campaign", IF(AND(C12>=VLOOKUP(M12,Cleaned_Campaign_Data!B:D,2,FALSE), C12<=VLOOKUP(M12,Cleaned_Campaign_Data!B:D,3,FALSE)), "During","Before")) -> Before
A13: P012 | B13: Facebook | C13: 45494 | D13: Reel | E13: Check out our latest reel on facebook! | F13: 1946 | G13: 686 | H13: 377 | I13: 23352 | J13: 22982 | K13: 213 | L13: #LiveForNow | M13: NewYearRefresh | N13: =IF(M13="","No Campaign", IF(AND(C13>=VLOOKUP(M13,Cleaned_Campaign_Data!B:D,2,FALSE), C13<=VLOOKUP(M13,Cleaned_Campaign_Data!B:D,3,FALSE)), "During","Before")) -> Before
A14: P013 | B14: YouTube | C14: 45614 | D14: Carousel | E14: Check out our latest carousel on youtube! | F14: 1171 | G14: 286 | H14: 231 | I14: 22249 | J14: 21282 | K14: 114 | L14: #ThirstyForMore | M14: SummerSplash | N14: =IF(M14="","No Campaign", IF(AND(C14>=VLOOKUP(M14,Cleaned_Campaign_Data!B:D,2,FALSE), C14<=VLOOKUP(M14,Cleaned_Campaign_Data!B:D,3,FALSE)), "During","Before")) -> Before
A15: P014 | B15: Facebook | C15: 45704 | D15: Story | E15: Check out our latest story on facebook! | F15: 4242 | G15: 555 | H15: 131 | I15: 33936 | J15: 33802 | K15: 265 | L15: #LiveForNow | N15: =IF(M15="","No Campaign", IF(AND(C15>=VLOOKUP(M15,Cleaned_Campaign_Data!B:D,2,FALSE), C15<=VLOOKUP(M15,Cleaned_Campaign_Data!B:D,3,FALSE)), "During","Before")) -> No Campaign
A16: P015 | B16: Facebook | C16: 45589 | D16: Video | E16: Check out our latest video on facebook! | F16: 3888 | G16: 604 | H16: 128 | I16: 77760 | J16: 77167 | K16: 20 | L16: #LiveForNow | M16: SummerSplash | N16: =IF(M16="","No Campaign", IF(AND(C16>=VLOOKUP(M16,Cleaned_Campaign_Data!B:D,2,FALSE), C16<=VLOOKUP(M16,Cleaned_Campaign_Data!B:D,3,FALSE)), "During","Before")) -> Before
A17: P016 | B17: Facebook | C17: 45530 | D17: Text | E17: Check out our latest text on facebook! | F17: 3452 | G17: 377 | H17: 360 | I17: 55232 | J17: 55075 | K17: 87 | L17: #LiveForNow | M17: NewYearRefresh | N17: =IF(M17="","No Campaign", IF(AND(C17>=VLOOKUP(M17,Cleaned_Campaign_Data!B:D,2,FALSE), C17<=VLOOKUP(M17,Cleaned_Campaign_Data!B:D,3,FALSE)), "During","Before")) -> Before
A18: P017 | B18: Facebook | C18: 45782 | D18: Text | E18: Check out our latest text on facebook! | F18: 4441 | G18: 511 | H18: 70 | I18: 53292 | J18: 53082 | K18: 159 | L18: #ThirstyForMore | M18: DailyWellness | N18: =IF(M18="","No Campaign", IF(AND(C18>=VLOOKUP(M18,Cleaned_Campaign_Data!B:D,2,FALSE), C18<=VLOOKUP(M18,Cleaned_Campaign_Data!B:D,3,FALSE)), "During","Before")) -> Before
A19: P018 | B19: Instagram | C19: 45523 | D19: Reel | E19: Check out our latest reel on instagram! | F19: 3000 | G19: 382 | H19: 325 | I19: 36000 | J19: 35819 | K19: 19 | L19: #LiveForNow | M19: SummerSplash | N19: =IF(M19="","No Campaign", IF(AND(C19>=VLOOKUP(M19,Cleaned_Campaign_Data!B:D,2,FALSE), C19<=VLOOKUP(M19,Cleaned_Campaign_Data!B:D,3,FALSE)), "During","Before")) -> Before
A20: P019 | B20: Instagram | C20: 45466 | D20: Video | E20: Check out our latest video on instagram! | F20: 1071 | G20: 519 | H20: 22 | I20: 16065 | J20: 15865 | K20: 103 | L20: #PepsiCoRefresh | M20: DailyWellness | N20: =IF(M20="","No Campaign", IF(AND(C20>=VLOOKUP(M20,Cleaned_Campaign_Data!B:D,2,FALSE), C20<=VLOOKUP(M20,Cleaned_Campaign_Data!B:D,3,FALSE)), "During","Before")) -> Before
A21: P020 | B21: Instagram | C21: 45544 | D21: Carousel | E21: Check out our latest carousel on instagram! | F21: 4054 | G21: 488 | H21: 373 | I21: 77026 | J21: 76881 | K21: 25 | L21: #PepsiCoRefresh | M21: SummerSplash | N21: =IF(M21="","No Campaign", IF(AND(C21>=VLOOKUP(M21,Cleaned_Campaign_Data!B:D,2,FALSE), C21<=VLOOKUP(M21,Cleaned_Campaign_Data!B:D,3,FALSE)), "During","Before")) -> Before
A22: P021 | B22: Instagram | C22: 45661 | D22: Reel | E22: Check out our latest reel on instagram! | F22: 4838 | G22: 640 | H22: 128 | I22: 72570 | J22: 72396 | K22: 83 | L22: #LiveForNow | M22: DailyWellness | N22: =IF(M22="","No Campaign", IF(AND(C22>=VLOOKUP(M22,Cleaned_Campaign_Data!B:D,2,FALSE), C22<=VLOOKUP(M22,Cleaned_Campaign_Data!B:D,3,FALSE)), "During","Before")) -> Before
A23: P022 | B23: Facebook | C23: 45715 | D23: Text | E23: Check out our latest text on facebook! | F23: 1570 | G23: 187 | H23: 260 | I23: 25120 | J23: 24613 | K23: 133 | L23: #PepsiCoRefresh | M23: DailyWellness | N23: =IF(M23="","No Campaign", IF(AND(C23>=VLOOKUP(M23,Cleaned_Campaign_Data!B:D,2,FALSE), C23<=VLOOKUP(M23,Cleaned_Campaign_Data!B:D,3,FALSE)), "During","Before")) -> Before
A24: P023 | B24: Facebook | C24: 45602 | D24: Video | E24: Check out our latest video on facebook! | F24: 1606 | G24: 547 | H24: 316 | I24: 32120 | J24: 31736 | K24: 225 | L24: #PepsiCoRefresh,#AnytimeIsPepsiTime | M24: FestiveRadiance | N24: =IF(M24="","No Campaign", IF(AND(C24>=VLOOKUP(M24,Cleaned_Campaign_Data!B:D,2,FALSE), C24<=VLOOKUP(M24,Cleaned_Campaign_Data!B:D,3,FALSE)), "During","Before")) -> Before
A25: P024 | B25: Facebook | C25: 45680 | D25: Video | E25: Check out our latest video on facebook! | F25: 3961 | G25: 761 | H25: 131 | I25: 67337 | J25: 66615 | K25: 161 | L25: #LiveForNow | M25: NewYearRefresh | N25: =IF(M25="","No Campaign", IF(AND(C25>=VLOOKUP(M25,Cleaned_Campaign_Data!B:D,2,FALSE), C25<=VLOOKUP(M25,Cleaned_Campaign_Data!B:D,3,FALSE)), "During","Before")) -> Before
A26: P025 | B26: Twitter | C26: 45757 | D26: Carousel | E26: Check out our latest carousel on twitter! | F26: 3128 | G26: 211 | H26: 197 | I26: 59432 | J26: 59182 | K26: 238 | L26: #ThirstyForMore | N26: =IF(M26="","No Campaign", IF(AND(C26>=VLOOKUP(M26,Cleaned_Campaign_Data!B:D,2,FALSE), C26<=VLOOKUP(M26,Cleaned_Campaign_Data!B:D,3,FALSE)), "During","Before")) -> No Campaign
A27: P026 | B27: YouTube | C27: 45752 | D27: Reel | E27: Check out our latest reel on youtube! | F27: 3009 | G27: 413 | H27: 358 | I27: 42126 | J27: 41309 | K27: 211 | L27: #LiveForNow | M27: FestiveRadiance | N27: =IF(M27="","No Campaign", IF(AND(C27>=VLOOKUP(M27,Cleaned_Campaign_Data!B:D,2,FALSE), C27<=VLOOKUP(M27,Cleaned_Campaign_Data!B:D,3,FALSE)), "During","Before")) -> Before
A28: P027 | B28: YouTube | C28: 45552 | D28: Text | E28: Check out our latest text on youtube! | F28: 2076 | G28: 195 | H28: 104 | I28: 33216 | J28: 32244 | K28: 51 | L28: #LiveForNow | M28: DailyWellness | N28: =IF(M28="","No Campaign", IF(AND(C28>=VLOOKUP(M28,Cleaned_Campaign_Data!B:D,2,FALSE), C28<=VLOOKUP(M28,Cleaned_Campaign_Data!B:D,3,FALSE)), "During","Before")) -> Before
A29: P028 | B29: Instagram | C29: 45720 | D29: Video | E29: Check out our latest video on instagram! | F29: 432 | G29: 624 | H29: 123 | I29: 6912 | J29: 6259 | K29: 79 | L29: #LiveForNow | M29: DailyWellness | N29: =IF(M29="","No Campaign", IF(AND(C29>=VLOOKUP(M29,Cleaned_Campaign_Data!B:D,2,FALSE), C29<=VLOOKUP(M29,Cleaned_Campaign_Data!B:D,3,FALSE)), "During","Before")) -> During
A30: P029 | B30: Instagram | C30: 45688 | D30: Carousel | E30: Check out our latest carousel on instagram! | F30: 2566 | G30: 118 | H30: 37 | I30: 12830 | J30: 12264 | K30: 221 | L30: #LiveForNow | M30: NewYearRefresh | N30: =IF(M30="","No Campaign", IF(AND(C30>=VLOOKUP(M30,Cleaned_Campaign_Data!B:D,2,FALSE), C30<=VLOOKUP(M30,Cleaned_Campaign_Data!B:D,3,FALSE)), "During","Before")) -> Before
A31: P030 | B31: Instagram | C31: 45713 | D31: Video | E31: Check out our latest video on instagram! | F31: 3095 | G31: 39 | H31: 78 | I31: 55710 | J31: 54808 | K31: 93 | L31: #ThirstyForMore | N31: =IF(M31="","No Campaign", IF(AND(C31>=VLOOKUP(M31,Cleaned_Campaign_Data!B:D,2,FALSE), C31<=VLOOKUP(M31,Cleaned_Campaign_Data!B:D,3,FALSE)), "During","Before")) -> No Campaign
A32: P031 | B32: Instagram | C32: 45642 | D32: Text | E32: Check out our latest text on instagram! | F32: 438 | G32: 153 | H32: 275 | I32: 3066 | J32: 2701 | K32: 282 | L32: #PepsiCoRefresh | M32: FestiveRadiance | N32: =IF(M32="","No Campaign", IF(AND(C32>=VLOOKUP(M32,Cleaned_Campaign_Data!B:D,2,FALSE), C32<=VLOOKUP(M32,Cleaned_Campaign_Data!B:D,3,FALSE)), "During","Before")) -> Before
A33: P032 | B33: Twitter | C33: 45504 | D33: Carousel | E33: Check out our latest carousel on twitter! | F33: 2278 | G33: 10 | H33: 321 | I33: 13668 | J33: 12676 | K33: 275 | L33: #ThirstyForMore | M33: SummerSplash | N33: =IF(M33="","No Campaign", IF(AND(C33>=VLOOKUP(M33,Cleaned_Campaign_Data!B:D,2,FALSE), C33<=VLOOKUP(M33,Cleaned_Campaign_Data!B:D,3,FALSE)), "During","Before")) -> Before
A34: P033 | B34: Facebook | C34: 45525 | D34: Image | E34: Check out our latest image on facebook! | F34: 1407 | G34: 400 | H34: 351 | I34: 16884 | J34: 15954 | K34: 113 | L34: #PepsiCoRefresh | M34: SummerSplash | N34: =IF(M34="","No Campaign", IF(AND(C34>=VLOOKUP(M34,Cleaned_Campaign_Data!B:D,2,FALSE), C34<=VLOOKUP(M34,Cleaned_Campaign_Data!B:D,3,FALSE)), "During","Before")) -> Before
A35: P034 | B35: Facebook | C35: 45742 | D35: Text | E35: Check out our latest text on facebook! | F35: 1652 | G35: 89 | H35: 357 | I35: 29736 | J35: 28771 | K35: 215 | L35: #PepsiCoRefresh | M35: NewYearRefresh | N35: =IF(M35="","No Campaign", IF(AND(C35>=VLOOKUP(M35,Cleaned_Campaign_Data!B:D,2,FALSE), C35<=VLOOKUP(M35,Cleaned_Campaign_Data!B:D,3,FALSE)), "During","Before")) -> Before
A36: P035 | B36: Instagram | C36: 45626 | D36: Video | E36: Check out our latest video on instagram! | F36: 3775 | G36: 16 | H36: 239 | I36: 33975 | J36: 33310 | K36: 271 | L36: #LiveForNow | M36: FestiveRadiance | N36: =IF(M36="","No Campaign", IF(AND(C36>=VLOOKUP(M36,Cleaned_Campaign_Data!B:D,2,FALSE), C36<=VLOOKUP(M36,Cleaned_Campaign_Data!B:D,3,FALSE)), "During","Before")) -> Before
A37: P036 | B37: Instagram | C37: 45766 | D37: Story | E37: Check out our latest story on instagram! | F37: 4518 | G37: 285 | H37: 383 | I37: 67770 | J37: 67621 | K37: 31 | L37: #ThirstyForMore | M37: FestiveRadiance | N37: =IF(M37="","No Campaign", IF(AND(C37>=VLOOKUP(M37,Cleaned_Campaign_Data!B:D,2,FALSE), C37<=VLOOKUP(M37,Cleaned_Campaign_Data!B:D,3,FALSE)), "During","Before")) -> Before
A38: P037 | B38: Facebook | C38: 45663 | D38: Carousel | E38: Check out our latest carousel on facebook! | F38: 3024 | G38: 925 | H38: 350 | I38: 24192 | J38: 23518 | K38: 36 | L38: #ThirstyForMore | M38: FestiveRadiance | N38: =IF(M38="","No Campaign", IF(AND(C38>=VLOOKUP(M38,Cleaned_Campaign_Data!B:D,2,FALSE), C38<=VLOOKUP(M38,Cleaned_Campaign_Data!B:D,3,FALSE)), "During","Before")) -> Before
A39: P038 | B39: YouTube | C39: 45705 | D39: Reel | E39: Check out our latest reel on youtube! | F39: 3138 | G39: 123 | H39: 291 | I39: 28242 | J39: 27550 | K39: 87 | L39: #PepsiCoRefresh | M39: DailyWellness | N39: =IF(M39="","No Campaign", IF(AND(C39>=VLOOKUP(M39,Cleaned_Campaign_Data!B:D,2,FALSE), C39<=VLOOKUP(M39,Cleaned_Campaign_Data!B:D,3,FALSE)), "During","Before")) -> Before
A40: P039 | B40: Facebook | C40: 45621 | D40: Image | E40: Check out our latest image on facebook! | F40: 3564 | G40: 629 | H40: 177 | I40: 60588 | J40: 59627 | K40: 92 | L40: #PepsiCoRefresh | N40: =IF(M40="","No Campaign", IF(AND(C40>=VLOOKUP(M40,Cleaned_Campaign_Data!B:D,2,FALSE), C40<=VLOOKUP(M40,Cleaned_Campaign_Data!B:D,3,FALSE)), "During","Before")) -> No Campaign
...

Sheet Cleaned_Engagement
A1: Week_Start_Date | B1: Platform | C1: New_Followers | D1: Unfollows | E1: Total_Followers | F1: Engagement_Rate | G1: Ad_Spend | H1: Net_Follower_Growth | I1: Campaign_Name
A2: 45446 | B2: Instagram | C2: 1135 | D2: 88 | E2: 344084 | F2: 8.06 | G2: 5904 | H2: =C2 - D2 -> 1047 | I2: {=IFERROR( INDEX(Cleaned_Campaign_Data!$B:$B, MATCH(1, (A2>=Cleaned_Campaign_Data!$C:$C)* (A2<=Cleaned_Campaign_Data!$D:$D), 0) ), "No Campaign" )} -> No Campaign
A3: 45446 | B3: Facebook | C3: 1312 | D3: 310 | E3: 42654 | F3: 4.98 | G3: 9566 | H3: =C3 - D3 -> 1002 | I3: {=IFERROR( INDEX(Cleaned_Campaign_Data!$B:$B, MATCH(1, (A3>=Cleaned_Campaign_Data!$C:$C)* (A3<=Cleaned_Campaign_Data!$D:$D), 0) ), "No Campaign" )} -> No Campaign
A4: 45446 | B4: Twitter | C4: 584 | D4: 169 | E4: 146834 | F4: 8.31 | G4: 26752 | H4: =C4 - D4 -> 415 | I4: {=IFERROR( INDEX(Cleaned_Campaign_Data!$B:$B, MATCH(1, (A4>=Cleaned_Campaign_Data!$C:$C)* (A4<=Cleaned_Campaign_Data!$D:$D), 0) ), "No Campaign" )} -> No Campaign
A5: 45446 | B5: YouTube | C5: 1535 | D5: 445 | E5: 395536 | F5: 4.11 | G5: 30671 | H5: =C5 - D5 -> 1090 | I5: {=IFERROR( INDEX(Cleaned_Campaign_Data!$B:$B, MATCH(1, (A5>=Cleaned_Campaign_Data!$C:$C)* (A5<=Cleaned_Campaign_Data!$D:$D), 0) ), "No Campaign" )} -> No Campaign
A6: 45453 | B6: Instagram | C6: 656 | D6: 139 | E6: 49157 | F6: 9.05 | G6: 9920 | H6: =C6 - D6 -> 517 | I6: {=IFERROR( INDEX(Cleaned_Campaign_Data!$B:$B, MATCH(1, (A6>=Cleaned_Campaign_Data!$C:$C)* (A6<=Cleaned_Campaign_Data!$D:$D), 0) ), "No Campaign" )} -> No Campaign
A7: 45453 | B7: Facebook | C7: 1697 | D7: 414 | E7: 316555 | F7: 2.37 | G7: 7924 | H7: =C7 - D7 -> 1283 | I7: {=IFERROR( INDEX(Cleaned_Campaign_Data!$B:$B, MATCH(1, (A7>=Cleaned_Campaign_Data!$C:$C)* (A7<=Cleaned_Campaign_Data!$D:$D), 0) ), "No Campaign" )} -> No Campaign
A8: 45453 | B8: Twitter | C8: 436 | D8: 250 | E8: 254347 | F8: 4.01 | G8: 8912 | H8: =C8 - D8 -> 186 | I8: {=IFERROR( INDEX(Cleaned_Campaign_Data!$B:$B, MATCH(1, (A8>=Cleaned_Campaign_Data!$C:$C)* (A8<=Cleaned_Campaign_Data!$D:$D), 0) ), "No Campaign" )} -> No Campaign
A9: 45453 | B9: YouTube | C9: 1197 | D9: 203 | E9: 413878 | F9: 3.16 | G9: 21205 | H9: =C9 - D9 -> 994 | I9: {=IFERROR( INDEX(Cleaned_Campaign_Data!$B:$B, MATCH(1, (A9>=Cleaned_Campaign_Data!$C:$C)* (A9<=Cleaned_Campaign_Data!$D:$D), 0) ), "No Campaign" )} -> No Campaign
A10: 45460 | B10: Instagram | C10: 1048 | D10: 155 | E10: 456946 | F10: 2.46 | G10: 11329 | H10: =C10 - D10 -> 893 | I10: {=IFERROR( INDEX(Cleaned_Campaign_Data!$B:$B, MATCH(1, (A10>=Cleaned_Campaign_Data!$C:$C)* (A10<=Cleaned_Campaign_Data!$D:$D), 0) ), "No Campaign" )} -> SummerSplash
A11: 45460 | B11: Facebook | C11: 1753 | D11: 371 | E11: 169496 | F11: 8.11 | G11: 46670 | H11: =C11 - D11 -> 1382 | I11: {=IFERROR( INDEX(Cleaned_Campaign_Data!$B:$B, MATCH(1, (A11>=Cleaned_Campaign_Data!$C:$C)* (A11<=Cleaned_Campaign_Data!$D:$D), 0) ), "No Campaign" )} -> SummerSplash
A12: 45460 | B12: Twitter | C12: 1335 | D12: 40 | E12: 122732 | F12: 8.19 | G12: 22482 | H12: =C12 - D12 -> 1295 | I12: {=IFERROR( INDEX(Cleaned_Campaign_Data!$B:$B, MATCH(1, (A12>=Cleaned_Campaign_Data!$C:$C)* (A12<=Cleaned_Campaign_Data!$D:$D), 0) ), "No Campaign" )} -> SummerSplash
A13: 45460 | B13: YouTube | C13: 403 | D13: 66 | E13: 382851 | F13: 3.49 | G13: 24313 | H13: =C13 - D13 -> 337 | I13: {=IFERROR( INDEX(Cleaned_Campaign_Data!$B:$B, MATCH(1, (A13>=Cleaned_Campaign_Data!$C:$C)* (A13<=Cleaned_Campaign_Data!$D:$D), 0) ), "No Campaign" )} -> SummerSplash
... A201: 45789 | B201: YouTube | C201: 119 | D201: 456 | E201: 82558 | F201: 6.81 | G201: 12174 | H201: =C201 - D201 -> -337 | I201: {=IFERROR( INDEX(Cleaned_Campaign_Data!$B:$B, MATCH(1, (A201>=Cleaned_Campaign_Data!$C:$C)* (A201<=Cleaned_Campaign_Data!$D:$D), 0) ), "No Campaign" )} -> No Campaign

Sheet Raw_Campaign_Data
A1: Campaign_Name | B1: Start_Date | C1: End_Date | D1: Objective | E1: Total_Budget | F1: Target_Platforms | G1: Primary_Hashtags
A2: SummerSplash | B2: 45458 | C2: 45488 | D2: Brand Awareness | E2: 150000 | F2: Instagram,Facebook | G2: #ThirstyForMore,#PepsiCoRefresh
A3: FestiveRadiance | B3: 45566 | C3: 45596 | D3: Engagement | E3: 200000 | F3: Instagram,YouTube | G3: #AnytimeIsPepsiTime,
A4: NewYearRefresh | B4: 45651 | C4: 45667 | D4: Product Launch | E4: 250000 | F4: Facebook,Twitter | G4: #SmoothLikeNitroPepsi
A5: DailyWellness | B5: 45717 | C5: 45747 | D5: Traffic | E5: 180000 | F5: Instagram,Twitter | G5: #BetterWithPepsi,#LiveForNow

Sheet Cleaned_Campaign_Data
A1: Campaign_ID | B1: Campaign_Name | C1: Start_Date | D1: End_Date | E1: Objective | F1: Ad_Spend | G1: Platform_1 | H1: Platform_2 | I1: Primary_Hashtags
A2: C001 | B2: SummerSplash | C2: 45458 | D2: 45488 | E2: Brand Awareness | F2: 150000 | G2: Instagram | H2: Facebook | I2: #ThirstyForMore,#PepsiCoRefresh
A3: C002 | B3: FestiveRadiance | C3: 45566 | D3: 45596 | E3: Engagement | F3: 200000 | G3: Instagram | H3: YouTube | I3: #AnytimeIsPepsiTime,
A4: C003 | B4: NewYearRefresh | C4: 45651 | D4: 45667 | E4: Product Launch | F4: 250000 | G4: Facebook | H4: Twitter | I4: #SmoothLikeNitroPepsi
A5: C004 | B5: DailyWellness | C5: 45717 | D5: 45747 | E5: Traffic | F5: 180000 | G5: Instagram | H5: Twitter | I5: #BetterWithPepsi,#LiveForNow

Sheet Campaign_Performance
A1: Likes | B1: Impressions | C1: Clicks | D1: Campaign_Name
A2: 1461 | B2: 21915 | C2: 15 | D2: SummerSplash
A3: 4054 | B3: 64864 | C3: 117 | D3: FestiveRadiance
A4: 2795 | B4: 53105 | C4: 204 | D4: NewYearRefresh
A5: 2404 | B5: 19232 | C5: 128 | D5: DailyWellness
A6: 3557 | B6: 71140 | C6: 224 | D6: SummerSplash
A7: 2945 | B7: 23560 | C7: 256 | D7: FestiveRadiance
A8: 3860 | B8: 61760 | C8: 235 | D8: FestiveRadiance
A9: 3929 | B9: 43219 | C9: 39 | D9: DailyWellness
A10: 3784 | B10: 56760 | C10: 131 | D10: FestiveRadiance
A11: 4241 | B11: 72097 | C11: 167 | D11: FestiveRadiance
A12: 1792 | B12: 25088 | C12: 65 | D12: DailyWellness
A13: 1946 | B13: 23352 | C13: 213 | D13: NewYearRefresh
A14: 1171 | B14: 22249 | C14: 114 | D14: SummerSplash
A15: 4242 | B15: 33936 | C15: 265
A16: 3888 | B16: 77760 | C16: 20 | D16: SummerSplash
A17: 3452 | B17: 55232 | C17: 87 | D17: NewYearRefresh
A18: 4441 | B18: 53292 | C18: 159 | D18: DailyWellness
A19: 3000 | B19: 36000 | C19: 19 | D19: SummerSplash
A20: 1071 | B20: 16065 | C20: 103 | D20: DailyWellness
A21: 4054 | B21: 77026 | C21: 25 | D21: SummerSplash
A22: 4838 | B22: 72570 | C22: 83 | D22: DailyWellness
A23: 1570 | B23: 25120 | C23: 133 | D23: DailyWellness
A24: 1606 | B24: 32120 | C24: 225 | D24: FestiveRadiance
A25: 3961 | B25: 67337 | C25: 161 | D25: NewYearRefresh
A26: 3128 | B26: 59432 | C26: 238
A27: 3009 | B27: 42126 | C27: 211 | D27: FestiveRadiance
A28: 2076 | B28: 33216 | C28: 51 | D28: DailyWellness
A29: 432 | B29: 6912 | C29: 79 | D29: DailyWellness
A30: 2566 | B30: 12830 | C30: 221 | D30: NewYearRefresh
A31: 3095 | B31: 55710 | C31: 93
A32: 438 | B32: 3066 | C32: 282 | D32: FestiveRadiance
A33: 2278 | B33: 13668 | C33: 275 | D33: SummerSplash
A34: 1407 | B34: 16884 | C34: 113 | D34: SummerSplash
A35: 1652 | B35: 29736 | C35: 215 | D35: NewYearRefresh
A36: 3775 | B36: 33975 | C36: 271 | D36: FestiveRadiance
A37: 4518 | B37: 67770 | C37: 31 | D37: FestiveRadiance
A38: 3024 | B38: 24192 | C38: 36 | D38: FestiveRadiance
A39: 3138 | B39: 28242 | C39: 87 | D39: DailyWellness
A40: 3564 | B40: 60588 | C40: 92
...

Sheet Campaign_Metrics_Summary
A1: Total And Average Impresions, Likes,Clicks Per Campaign
A3: Row Labels | B3: Sum of Impressions | C3: Average of Impressions2 | D3: Sum of Likes | E3: Average of Likes2 | F3: Sum of Clicks | G3: Average of Clicks2
A4: DailyWellness | B4: 2464864 | C4: 34716.394 | D4: 187909 | E4: 2646.6056 | F4: 10689 | G4: 150.5493
A5: FestiveRadiance | B5: 1986356 | C5: 34247.517 | D5: 159783 | E5: 2754.8793 | F5: 9872 | G5: 170.2069
A6: NewYearRefresh | B6: 2266053 | C6: 33821.687 | D6: 183346 | E6: 2736.5075 | F6: 10032 | G6: 149.73134
A7: SummerSplash | B7: 1846272 | C7: 38464 | D7: 138793 | E7: 2891.5208 | F7: 6434 | G7: 134.04167
A8: (blank) | B8: 1830608 | C8: 32689.429 | D8: 150160 | E8: 2681.4286 | F8: 8339 | G8: 148.91071
A9: Grand Total | B9: 10394153 | C9: 34647.177 | D9: 819991 | E9: 2733.3033 | F9: 45366 | G9: 151.22

Sheet Campaign_Uplift_Analysis
B3: Column Labels
B4: Before | E4: During | H4: Total Average of Likes | I4: Total Average of Clicks | J4: Total Average of Impressions
A5: Row Labels | B5: Average of Likes | C5: Average of Clicks | D5: Average of Impressions | E5: Average of Likes | F5: Average of Clicks | G5: Average of Impressions
A6: DailyWellness | B6: 2695.3016 | C6: 151.19048 | D6: 35151.016 | E6: 2263.125 | F6: 145.5 | G6: 31293.75 | H6: 2646.6056 | I6: 150.5493 | J6: 34716.394
A7: FestiveRadiance | B7: 2740.2941 | C7: 163.68627 | D7: 34716.196 | E7: 2861.1429 | F7: 217.71429 | G7: 30832.857 | H7: 2754.8793 | I7: 170.2069 | J7: 34247.517
A8: NewYearRefresh | B8: 2751.3125 | C8: 148.32812 | D8: 34592.266 | E8: 2420.6667 | F8: 179.66667 | G8: 17382.667 | H8: 2736.5075 | I8: 149.73134 | J8: 33821.687
A9: SummerSplash | B9: 2883.4186 | C9: 129.90698 | D9: 36718.535 | E9: 2961.2 | F9: 169.6 | G9: 53475 | H9: 2891.5208 | I9: 134.04167 | J9: 38464
A10: Grand Total | B10: 2758.5068 | C10: 149.10407 | D10: 35193.855 | E10: 2617.4348 | F10: 177.17391 | G10: 34161 | H10: 2745.209 | I10: 151.75 | J10: 35096.496
A14: Engagement Uplift During VS Before

Sheet ROI_Analysis
A1: Campaign_Name | B1: Ad_Spend | C1: Total_Likes | D1: Total Clicks | E1: Total_Engagement | F1: ROI
A2: SummerSplash | B2: 150000 | C2: 138793 | D2: 6434 | E2: =C2 + D2 -> 145227 | F2: =E2 / B2 -> 0.96818
A3: FestiveRadiance | B3: 200000 | C3: 159783 | D3: 9872 | E3: =C3 + D3 -> 169655 | F3: =E3 / B3 -> 0.848275
A4: NewYearRefresh | B4: 250000 | C4: 183346 | D4: 10032 | E4: =C4 + D4 -> 193378 | F4: =E4 / B4 -> 0.773512
A5: DailyWellness | B5: 180000 | C5: 187909 | D5: 10689 | E5: =C5 + D5 -> 198598 | F5: =E5 / B5 -> 1.1033222

Sheet Follower_Growth_Impact
A1: Follower_Growth_Impact
A3: Row Labels | B3: Sum of Net_Follower_Growth
A4: DailyWellness | B4: 16078
A5: SummerSplash | B5: 13523
A6: FestiveRadiance | B6: 11092
A7: NewYearRefresh | B7: 10087
A8: Grand Total | B8: 50780

Sheet Insights_Task5
A1: • SummerSplash delivered the highest ROI | B1: generating the strongest engagement relative to its allocated budget | C1: making it the most cost-efficient campaign.
A3: • DailyWellness achieved the highest net follower growth (16078) | B3: indicating the strongest long-term audience acquisition impact.
A5: • Click performance improved during all campaigns compared to the pre-campaign period | B5: confirming that campaign CTAs and targeting were effective.
A7: • Likes uplift was observed in 2 out of 4 campaigns during the campaign period | B7: showing that creative effectiveness varied by campaign theme.
A9: • Impressions increased during the campaign window for one campaign | B9: while others remained flat | C9: indicating selective reach amplification rather than universal exposure growth.
